
<!-- This URDF was automatically created by SolidWorks to URDF Exporter! Originally created by Stephen Brawner (brawner@gmail.com) 
     Commit Version: 1.6.0-4-g7f85cfe  Build Version: 1.6.7995.38578
     For more information, please see http://wiki.ros.org/sw_urdf_exporter -->
<robot
  name="treewheel_mobile">
  <link
    name="base_link">
    <inertial>
      <origin
        xyz="-0.0073563 -1.1796E-16 -0.0071395"
        rpy="0 0 0" />
      <mass
        value="0.12" />
      <inertia
        ixx="0.0001"
        ixy="0"
        ixz="0"
        iyy="0.0003"
        iyz="0"
        izz="0.0002" />
    </inertial>
    <visual>
      <origin
        xyz="0 0 0"
        rpy="0 0 0" />
      <geometry>
        <mesh
          filename="package://mobile_robot/meshes/base_link.STL" />
      </geometry>
      <material
        name="">
        <color
          rgba="1 1 1 0.3" />
      </material>
    </visual>
    <collision>
      <origin
        xyz="0 0 0"
        rpy="0 0 0" />
      <geometry>
        <mesh
          filename="package://mobile_robot/meshes/base_link.STL" />
      </geometry>
    </collision>
  </link>
  
<gazebo reference="base_link">
  <mu1>0.2</mu1>
  <mu2>0.2</mu2>
  <kp>1000</kp>
  <kd>10</kd>
  <material>Gazebo/Red</material>
</gazebo>
  
  <link
    name="left_wheel">
    <inertial>
      <origin
        xyz="2.2714E-09 -3.2445E-08 -0.0073729"
        rpy="0 0 0" />
      <mass
        value="0.14" />
      <inertia
        ixx="0.00002"
        ixy="0"
        ixz="0"
        iyy="0.00002"
        iyz="0"
        izz="0.0001" />
    </inertial>
    <visual>
      <origin
        xyz="0 0 0"
        rpy="0 0 0" />
      <geometry>
        <mesh
          filename="package://mobile_robot/meshes/left_wheel.STL" />
      </geometry>
      <material
        name="">
        <color
          rgba="0.79216 0.81961 0.93333 1" />
      </material>
    </visual>
    <collision>
      <origin
        xyz="0 0 0"
        rpy="0 0 0" />
      <geometry>
        <mesh
          filename="package://mobile_robot/meshes/left_wheel.STL" />
      </geometry>
    </collision>
  </link>
  <joint
    name="leftwheel"
    type="continuous">
    <origin
      xyz="-0.033259 0.07575 -0.01375"
      rpy="-1.5708 0 0" />
    <parent
      link="base_link" />
    <child
      link="left_wheel" />
    <axis
      xyz="0 0 -1" />
      
    <!---limit
      effort="10"
      velocity="10" /-->
      
    <dynamics
      damping="0.1"
      friction="0.1" />
  </joint>
  
<gazebo reference="left_wheel">
  <mu1>0.2</mu1>
  <mu2>0.2</mu2>
  <kp>1000</kp>
  <kd>10</kd>
  <material>Gazebo/Gray</material>
</gazebo>
  
  <link
    name="right_wheel">
    <inertial>
      <origin
        xyz="2.2714E-09 3.2445E-08 0.0073729"
        rpy="0 0 0" />
      <mass
        value="0.021404" />
      <inertia
        ixx="0.00002"
        ixy="0"
        ixz="0"
        iyy="0.00002"
        iyz="0"
        izz="0.0001" />
    </inertial>
    <visual>
      <origin
        xyz="0 0 0"
        rpy="0 0 0" />
      <geometry>
        <mesh
          filename="package://mobile_robot/meshes/right_wheel.STL" />
      </geometry>
      <material
        name="">
        <color
          rgba="0.79216 0.81961 0.93333 1" />
      </material>
    </visual>
    <collision>
      <origin
        xyz="0 0 0"
        rpy="0 0 0" />
      <geometry>
        <mesh
          filename="package://mobile_robot/meshes/right_wheel.STL" />
      </geometry>
    </collision>
  </link>
  
<gazebo reference="right_wheel">
  <mu1>0.2</mu1>
  <mu2>0.2</mu2>
  <kp>1000</kp>
  <kd>10</kd>
  <material>Gazebo/Gray</material>
</gazebo>
  
  <joint
    name="rightwheel"
    type="continuous">
    <origin
      xyz="-0.033259 -0.07575 -0.01375"
      rpy="-1.5708 0 0" />
    <parent
      link="base_link" />
    <child
      link="right_wheel" />
    <axis
      xyz="0 0 1" />
      
      
    <!---limit
      effort="10"
      velocity="10" /-->
      
      
    <dynamics
      damping="0.1"
      friction="0.1" />
  </joint>
  <link
    name="castor">
    <inertial>
      <origin
        xyz="0 0 0"
        rpy="0 0 0" />
      <mass
        value="0.046" />
      <inertia
        ixx="0.00004"
        ixy="0"
        ixz="0"
        iyy="0.00004"
        iyz="0"
        izz="0.00001" />
    </inertial>
    <visual>
      <origin
        xyz="0 0 0"
        rpy="0 0 3.142" />          <!--avec z=3.142 pour tourner la chassis-->
      <geometry>
        <mesh
          filename="package://mobile_robot/meshes/castor.STL" />
      </geometry>
      <material
        name="">
        <color
          rgba="0.63922 0.66667 0.67843 1" />
      </material>
    </visual>
    <collision>
      <origin
        xyz="0 0 0"
        rpy="0 0 0" />
      <geometry>
        <mesh
          filename="package://mobile_robot/meshes/castor.STL" />
      </geometry>
    </collision>
  </link>
  
<gazebo reference="castor">
  <mu1>0.1</mu1>
  <mu2>0.1</mu2>
  <kp>1000</kp>
  <kd>10</kd>
  <material>Gazebo/Gray</material>
</gazebo>
  
  <joint
    name="castorjoint"
    type="continuous">
    <origin
      xyz="0.072581 0 -0.0025"
      rpy="0 0 -3.142" />
    <parent
      link="base_link" />
    <child
      link="castor" />
    <axis
      xyz="0 0 1" />
      
      
    <!---limit
      effort="10"
      velocity="10" /-->
      
      
  </joint>
  <link
    name="castor_wheel">
    <inertial>
      <origin
        xyz="6.93889390390723E-18 -2.62037475051713E-11 -2.77710070911708E-09"
        rpy="0 0 0" />
      <mass
        value="0.0088" />
      <inertia
        ixx="0.0004"
        ixy="0"
        ixz="0"
        iyy="0.0004"
        iyz="0"
        izz="0.00001" />
    </inertial>
    <visual>
      <origin
        xyz="0 0 0"
        rpy="0 0 0" />
      <geometry>
        <mesh
          filename="package://mobile_robot/meshes/castor_wheel.STL" />
      </geometry>
      <material
        name="">
        <color
          rgba="1 1 1 1" />
      </material>
    </visual>
    <collision>
      <origin
        xyz="0 0 0"
        rpy="0 0 0" />
      <geometry>
        <mesh
          filename="package://mobile_robot/meshes/castor_wheel.STL" />
      </geometry>
    </collision>
  </link>
  
<gazebo reference="castor_wheel">
  <mu1>0.1</mu1>
  <mu2>0.1</mu2>
  <kp>1000</kp>
  <kd>10</kd>
  <material>Gazebo/Gray</material>
</gazebo>
  
  <joint
    name="castorwheel"
    type="continuous">
    <origin
      xyz="-0.015 0 -0.023"
      rpy="1.5708 0 0" />                 <!---j'ai mis z=3.142 pour tourner la roue-->
    <parent
      link="castor" />
    <child
      link="castor_wheel" />
    <axis
      xyz="-0.0094352 0 0.99996" />
      
    <!--limit
      effort="10"
      velocity="10" /-->
      
    <dynamics
      damping="0.1"
      friction="0.1" />
  </joint>
  
      <!-- New link for the structure -->
  <link name="top_structure">
    <inertial>
      <origin xyz="0 0 0" rpy="0 0 0" />
      <mass value="0.0001" />
      <inertia ixx="0.0001" ixy="0" ixz="0" iyy="0.0001" iyz="0" izz="0.0001" />
    </inertial>
    <visual>
      <origin xyz="0.01 0 0.008" rpy="0 0 0" />
      <geometry>
        <box size="0.151 0.0999 0.03" />
      </geometry>
      <material name="">
        <color rgba="0.8 0.8 0.8 1" />
      </material>
    </visual>
    <collision>
      <origin xyz="0 0 0" rpy="0 0 0" />
      <geometry>
        <box size="0.09 0.09 0.01" />
      </geometry>
    </collision>
  </link>
  <!-- Fixed joint to attach the structure to the base_link -->
  <joint name="structure_joint" type="fixed">
    <origin xyz="0 0 0.005" rpy="0 0 0" />
    <parent link="base_link" />
    <child link="top_structure" />
  </joint>
    <!-- Existing gazebo tags -->
  <gazebo reference="top_structure">
    <mu1>0.2</mu1>
    <mu2>0.2</mu2>
    <kp>1000</kp>
    <kd>10</kd>
    <material>Gazebo/Red</material>
  </gazebo>
  
  
  

  
</robot>
